<?xml version="1.0" ?>
<!-- SO-101 Robot with Paper-Square Task (Official Model) -->
<mujoco model="so101_paper_square_realistic">
  <compiler angle="radian" meshdir="official_model/assets" autolimits="true"/>
  <option timestep="0.001" gravity="0 0 -9.81" cone="elliptic"/>
  <!-- timestep = 1/1000 Hz (1ms) for stable physics simulation (improved from 360Hz) -->

  <!-- Laboratory workbench lighting -->
  <visual>
    <headlight ambient="0.4 0.4 0.4" diffuse="0.5 0.5 0.5" specular="0.1 0.1 0.1"/>
    <rgba haze="0.15 0.25 0.35 1"/>
    <quality shadowsize="2048"/>
    <map fogstart="3" fogend="5" force="0.05"/>
  </visual>

  <!-- Copy defaults from official model -->
  <default>
    <default class="so101_new_calib">
      <joint damping="1" frictionloss="0.1" armature="0.005"/>
      <position kp="50"/>
      <default class="visual">
        <geom type="mesh" contype="0" conaffinity="0" group="2"/>
      </default>
      <default class="collision">
        <geom group="0" contype="1" conaffinity="2"/>
      </default>
    </default>
    <default class="sts3215">
      <geom contype="0" conaffinity="0"/>
      <joint damping="0.60" frictionloss="0.052" armature="0.028"/>
      <position kp="17.8"/>
    </default>
    <!-- Task objects use different defaults -->
    <default class="task_objects">
      <geom condim="3" solref="0.005 1" solimp="0.9 0.95 0.001" friction="1 0.1 0.1" margin="0.001"/>
    </default>
  </default>

  <asset>
    <!-- Robot meshes -->
    <mesh file="waveshare_mounting_plate_so101_v2.stl"/>
    <mesh file="sts3215_03a_v1.stl"/>
    <mesh file="motor_holder_so101_base_v1.stl"/>
    <mesh file="wrist_roll_follower_so101_v1.stl"/>
    <mesh file="moving_jaw_so101_v1.stl"/>
    <mesh file="base_motor_holder_so101_v1.stl"/>
    <mesh file="upper_arm_so101_v1.stl"/>
    <mesh file="wrist_roll_pitch_so101_v2.stl"/>
    <mesh file="under_arm_so101_v1.stl"/>
    <mesh file="rotation_pitch_so101_v1.stl"/>
    <mesh file="motor_holder_so101_wrist_v1.stl"/>
    <mesh file="sts3215_03a_no_horn_v1.stl"/>
    <mesh file="base_so101_v2.stl"/>

    <!-- Robot materials (White body with blue gripper) -->
    <material name="base_motor_holder_so101_v1_material" rgba="0.95 0.95 0.95 1"/>
    <material name="base_so101_v2_material" rgba="0.95 0.95 0.95 1"/>
    <material name="sts3215_03a_v1_material" rgba="0.1 0.1 0.1 1"/>
    <material name="waveshare_mounting_plate_so101_v2_material" rgba="0.95 0.95 0.95 1"/>
    <material name="motor_holder_so101_base_v1_material" rgba="0.95 0.95 0.95 1"/>
    <material name="rotation_pitch_so101_v1_material" rgba="0.95 0.95 0.95 1"/>
    <material name="upper_arm_so101_v1_material" rgba="0.95 0.95 0.95 1"/>
    <material name="under_arm_so101_v1_material" rgba="0.95 0.95 0.95 1"/>
    <material name="motor_holder_so101_wrist_v1_material" rgba="0.95 0.95 0.95 1"/>
    <material name="sts3215_03a_no_horn_v1_material" rgba="0.1 0.1 0.1 1.0"/>
    <material name="wrist_roll_pitch_so101_v2_material" rgba="0.95 0.95 0.95 1"/>
    <material name="wrist_roll_follower_so101_v1_material" rgba="0.2 0.5 0.9 1"/>
    <material name="moving_jaw_so101_v1_material" rgba="0.2 0.5 0.9 1"/>

    <!-- Task environment materials -->
    <material name="matte_black" rgba="0.05 0.05 0.05 1" specular="0.0" shininess="0.0"/>
    <material name="white" rgba="0.95 0.95 0.95 1"/>
    <material name="red_tape" rgba="0.8 0.1 0.1 0.3"/>
    <!-- Gripper fingertip material (nitrile + work glove) -->
    <material name="gripper_rubber" rgba="0.3 0.3 0.3 1"/>
  </asset>

  <worldbody>
    <!-- Table/ground plane -->
    <body name="table" pos="0 0 0">
      <geom name="table_surface" type="plane" size="1 1 0.1" material="matte_black" friction="0.30 0.001 0.00005" contype="2" conaffinity="2" class="task_objects"/>
      <site name="table_center" pos="0 0 0.001" size="0.01" rgba="0 0 0 0"/>
    </body>

    <!-- SO-101 Robot (official model, positioned OUTSIDE red frame near origin) -->
    <!-- Base 100mm from closest corner outer edge (toward origin, parallel to long edge) -->
    <!-- Base 110mm from closest corner outer edge (toward origin, parallel to short edge) -->
    <!-- Rotated 45° from frame edges (45° CCW around Z-axis) -->
    <body name="base" pos="0.050 -0.029 0.02" quat="0.9239 0 0 0.3827" childclass="so101_new_calib">
      <inertial pos="0.0137179 -5.19711e-05 0.0334843" mass="0.147" fullinertia="0.000114686 0.000136117 0.000130364 -4.59787e-07 4.97151e-06 9.75275e-08"/>
      <!-- Part base_motor_holder_so101_v1 -->
      <geom type="mesh" class="visual" pos="-0.00636471 -9.94414e-05 -0.0024" quat="0.5 0.5 0.5 0.5" mesh="base_motor_holder_so101_v1" material="base_motor_holder_so101_v1_material"/>
      <!-- Part base_so101_v2 -->
      <geom type="mesh" class="visual" pos="-0.00636471 -8.97657e-09 -0.0024" quat="0.5 0.5 0.5 0.5" mesh="base_so101_v2" material="base_so101_v2_material"/>
      <!-- Part sts3215_03a_v1 -->
      <geom type="mesh" class="visual" pos="0.0263353 -8.97657e-09 0.0437" quat="1 -2.85511e-16 -9.64433e-17 6.12908e-16" mesh="sts3215_03a_v1" material="sts3215_03a_v1_material"/>
      <!-- Part waveshare_mounting_plate_so101_v2 -->
      <geom type="mesh" class="visual" pos="-0.0309827 -0.000199441 0.0474" quat="0.5 0.5 0.5 0.5" mesh="waveshare_mounting_plate_so101_v2" material="waveshare_mounting_plate_so101_v2_material"/>
      <!-- Frame baseframe -->
      <site group="3" name="baseframe" pos="8.67362e-19 9.55596e-18 3.46945e-18" quat="1 -8.17396e-19 3.78392e-17 2.22045e-16"/>

      <!-- Link shoulder -->
      <body name="shoulder" pos="0.0388353 -8.97657e-09 0.0624" quat="3.56167e-16 1.22818e-15 -1 -4.14635e-16">
        <!-- Joint from base to shoulder -->
        <joint axis="0 0 1" name="shoulder_pan" type="hinge" range="-1.9198621771937616 1.9198621771937634" class="sts3215"/>
        <inertial pos="-0.0307604 -1.66727e-05 -0.0252713" mass="0.100006" fullinertia="8.3759e-05 8.10403e-05 2.39783e-05 7.55525e-08 -1.16342e-06 1.54663e-07"/>
        <!-- Part sts3215_03a_v1_2 -->
        <geom type="mesh" class="visual" pos="-0.0303992 0.000422241 -0.0417" quat="0.5 0.5 0.5 -0.5" mesh="sts3215_03a_v1" material="sts3215_03a_v1_material"/>
        <geom type="mesh" class="collision" pos="-0.0303992 0.000422241 -0.0417" quat="0.5 0.5 0.5 -0.5" mesh="sts3215_03a_v1" material="sts3215_03a_v1_material"/>
        <!-- Part motor_holder_so101_base_v1 -->
        <geom type="mesh" class="visual" pos="-0.0675992 -0.000177759 0.0158499" quat="0.5 0.5 -0.5 0.5" mesh="motor_holder_so101_base_v1" material="motor_holder_so101_base_v1_material"/>
        <geom type="mesh" class="collision" pos="-0.0675992 -0.000177759 0.0158499" quat="0.5 0.5 -0.5 0.5" mesh="motor_holder_so101_base_v1" material="motor_holder_so101_base_v1_material"/>
        <!-- Part rotation_pitch_so101_v1 -->
        <geom type="mesh" class="visual" pos="0.0122008 2.22413e-05 0.0464" quat="0.707107 -0.707107 -0 8.3163e-34" mesh="rotation_pitch_so101_v1" material="rotation_pitch_so101_v1_material"/>
        <geom type="mesh" class="collision" pos="0.0122008 2.22413e-05 0.0464" quat="0.707107 -0.707107 -0 8.3163e-34" mesh="rotation_pitch_so101_v1" material="rotation_pitch_so101_v1_material"/>

        <!-- Link upper_arm -->
        <body name="upper_arm" pos="-0.0303992 -0.0182778 -0.0542" quat="0.5 -0.5 -0.5 -0.5">
          <!-- Joint from shoulder to upper_arm -->
          <joint axis="0 0 1" name="shoulder_lift" type="hinge" range="-1.7453292519943224 1.7453292519943366" class="sts3215"/>
          <inertial pos="-0.0898471 -0.00838224 0.0184089" mass="0.103" fullinertia="4.08002e-05 0.000147318 0.000142487 -1.97819e-05 -4.03016e-08 8.97326e-09"/>
          <!-- Part sts3215_03a_v1_3 -->
          <geom type="mesh" class="visual" pos="-0.11257 -0.0155 0.0187" quat="4.56308e-16 -0.707107 0.707107 -1.37383e-16" mesh="sts3215_03a_v1" material="sts3215_03a_v1_material"/>
          <geom type="mesh" class="collision" pos="-0.11257 -0.0155 0.0187" quat="4.56308e-16 -0.707107 0.707107 -1.37383e-16" mesh="sts3215_03a_v1" material="sts3215_03a_v1_material"/>
          <!-- Part upper_arm_so101_v1 -->
          <geom type="mesh" class="visual" pos="-0.065085 0.012 0.0182" quat="0 1 0 0" mesh="upper_arm_so101_v1" material="upper_arm_so101_v1_material"/>
          <geom type="mesh" class="collision" pos="-0.065085 0.012 0.0182" quat="0 1 0 0" mesh="upper_arm_so101_v1" material="upper_arm_so101_v1_material"/>

          <!-- Link lower_arm -->
          <body name="lower_arm" pos="-0.11257 -0.028 1.73763e-16" quat="0.707107 -5.98613e-17 -2.58051e-17 0.707107">
            <!-- Joint from upper_arm to lower_arm -->
            <joint axis="0 0 1" name="elbow_flex" type="hinge" range="-1.69 1.69" class="sts3215"/>
            <inertial pos="-0.0980701 0.00324376 0.0182831" mass="0.104" fullinertia="2.87438e-05 0.000159844 0.00014529 7.41152e-06 1.26409e-06 -4.90188e-08"/>
            <!-- Part under_arm_so101_v1 -->
            <geom type="mesh" class="visual" pos="-0.0648499 -0.032 0.0182" quat="0 1 0 0" mesh="under_arm_so101_v1" material="under_arm_so101_v1_material"/>
            <geom type="mesh" class="collision" pos="-0.0648499 -0.032 0.0182" quat="0 1 0 0" mesh="under_arm_so101_v1" material="under_arm_so101_v1_material"/>
            <!-- Part motor_holder_so101_wrist_v1 -->
            <geom type="mesh" class="visual" pos="-0.0648499 -0.032 0.018" quat="3.92687e-16 -1 -1.9186e-15 -6.38378e-16" mesh="motor_holder_so101_wrist_v1" material="motor_holder_so101_wrist_v1_material"/>
            <geom type="mesh" class="collision" pos="-0.0648499 -0.032 0.018" quat="3.92687e-16 -1 -1.9186e-15 -6.38378e-16" mesh="motor_holder_so101_wrist_v1" material="motor_holder_so101_wrist_v1_material"/>
            <!-- Part sts3215_03a_v1_4 -->
            <geom type="mesh" class="visual" pos="-0.1224 0.0052 0.0187" quat="7.21645e-16 1.56949e-15 1 -3.33067e-16" mesh="sts3215_03a_v1" material="sts3215_03a_v1_material"/>
            <geom type="mesh" class="collision" pos="-0.1224 0.0052 0.0187" quat="7.21645e-16 1.56949e-15 1 -3.33067e-16" mesh="sts3215_03a_v1" material="sts3215_03a_v1_material"/>

            <!-- Link wrist -->
            <body name="wrist" pos="-0.1349 0.0052 3.62355e-17" quat="0.707107 9.58722e-16 -7.51313e-16 -0.707107">
              <!-- Joint from lower_arm to wrist -->
              <joint axis="0 0 1" name="wrist_flex" type="hinge" range="-1.6580628494556928 1.6580627293335335" class="sts3215"/>
              <inertial pos="-0.000103312 -0.0386143 0.0281156" mass="0.079" fullinertia="3.68263e-05 2.5391e-05 2.1e-05 1.7893e-08 -5.28128e-08 3.6412e-06"/>
              <!-- Part sts3215_03a_no_horn_v1 -->
              <geom type="mesh" class="visual" pos="8.32667e-17 -0.0424 0.0306" quat="0.5 0.5 0.5 -0.5" mesh="sts3215_03a_no_horn_v1" material="sts3215_03a_no_horn_v1_material"/>
              <geom type="mesh" class="collision" pos="8.32667e-17 -0.0424 0.0306" quat="0.5 0.5 0.5 -0.5" mesh="sts3215_03a_no_horn_v1" material="sts3215_03a_no_horn_v1_material"/>
              <!-- Part wrist_roll_pitch_so101_v2 -->
              <geom type="mesh" class="visual" pos="0 -0.028 0.0181" quat="0.5 -0.5 -0.5 -0.5" mesh="wrist_roll_pitch_so101_v2" material="wrist_roll_pitch_so101_v2_material"/>
              <geom type="mesh" class="collision" pos="0 -0.028 0.0181" quat="0.5 -0.5 -0.5 -0.5" mesh="wrist_roll_pitch_so101_v2" material="wrist_roll_pitch_so101_v2_material"/>

              <!-- Link gripper -->
              <body name="gripper" pos="5.55112e-17 -0.0611 0.0181" quat="0.0172091 -0.0172091 0.706897 0.706897">
                <!-- Joint from wrist to gripper -->
                <joint axis="0 0 1" name="wrist_roll" type="hinge" range="-2.7438472969992493 2.841206309382605" class="sts3215"/>
                <inertial pos="0.000213627 0.000245138 -0.025187" mass="0.087" fullinertia="2.75087e-05 4.33657e-05 3.45059e-05 -3.35241e-07 -5.7352e-06 -5.17847e-08"/>
                <!-- Part sts3215_03a_v1_5 -->
                <geom type="mesh" class="visual" pos="0.0077 0.0001 -0.0234" quat="0.707107 -0.707107 1.66015e-15 6.45094e-15" mesh="sts3215_03a_v1" material="sts3215_03a_v1_material"/>
                <geom type="mesh" class="collision" pos="0.0077 0.0001 -0.0234" quat="0.707107 -0.707107 1.66015e-15 6.45094e-15" mesh="sts3215_03a_v1" material="sts3215_03a_v1_material"/>
                <!-- Part wrist_roll_follower_so101_v1 -->
                <geom type="mesh" class="visual" pos="8.32667e-17 -0.000218214 0.000949706" quat="0 1 0 0" mesh="wrist_roll_follower_so101_v1" material="wrist_roll_follower_so101_v1_material"/>
                <geom type="mesh" class="collision" pos="8.32667e-17 -0.000218214 0.000949706" quat="0 1 0 0" mesh="wrist_roll_follower_so101_v1" material="wrist_roll_follower_so101_v1_material"/>

                <!-- Fixed jaw fingertip: sphere at extreme finger tip for paper tossing/pushing -->
                <!-- High slide friction (μ=1.0) for paper contact, low spin/roll for realistic physics -->
                <!-- Position: 7mm below EE site in gripper frame (at actual jaw tip) -->
                <!-- PHASE A: contype="0" DISABLED (pushing-only training) -->
                <!-- PHASE B: Change to contype="2" to enable contact-based strategies -->
                <geom name="fixed_fingertip" type="sphere"
                      class="task_objects"
                      pos="-0.0079 -0.000218 -0.1050"
                      size="0.008"
                      material="gripper_rubber"
                      friction="1.0 0.003 0.0001"
                      contype="2"
                      conaffinity="2"/>

                <!-- Camera 2: Wrist-mounted camera for GR00T egocentric vision -->
                <!-- Mounted on wrist_roll_follower (hex-nut recess mounting point) -->
                <!-- 140° FOV for wide-angle close-up manipulation view -->
                <camera name="wrist_camera"
                        pos="0 -0.02 0.01"
                        euler="0 0.3 0"
                        fovy="140"/>

                <!-- Frame gripperframe -->
                <site group="3" name="gripperframe" pos="-0.0079 -0.000218121 -0.0981274" quat="0.707107 -0 0.707107 -2.37788e-17"/>
                <!-- End-effector site for RL -->
                <site name="ee_site" pos="-0.0079 -0.000218121 -0.0981274" size="0.005" rgba="0 1 0 0.5"/>

                <!-- Link moving_jaw_so101_v1 -->
                <body name="moving_jaw_so101_v1" pos="0.0202 0.0188 -0.0234" quat="0.707107 0.707107 -1.85362e-08 1.85362e-08">
                  <!-- Joint from gripper to moving_jaw_so101_v1 -->
                  <joint axis="0 0 1" name="gripper" type="hinge" range="-0.17453297762778586 1.7453291995659765" class="sts3215"/>
                  <inertial pos="-0.00157495 -0.0300244 0.0192755" mass="0.012" fullinertia="6.61427e-06 1.89032e-06 5.28738e-06 -3.19807e-07 -5.90717e-09 -1.09945e-07"/>
                  <!-- Part moving_jaw_so101_v1 -->
                  <geom type="mesh" class="visual" pos="-5.55112e-17 -5.55112e-17 0.0189" quat="1 -0 3.00524e-16 -2.00834e-17" mesh="moving_jaw_so101_v1" material="moving_jaw_so101_v1_material"/>
                  <geom type="mesh" class="collision" pos="-5.55112e-17 -5.55112e-17 0.0189" quat="1 -0 3.00524e-16 -2.00834e-17" mesh="moving_jaw_so101_v1" material="moving_jaw_so101_v1_material"/>

                  <!-- Moving jaw fingertip: Extrema-based calibration from STL geometry -->
                  <!-- High slide friction (μ=1.0) for paper contact, low spin/roll for realistic physics -->
                  <!-- Position: MIN Y extremum, outermost surface point (extends outside gripper body) -->
                  <!-- Method: Opposite end from hinge, MAX Z among MIN Y vertices for surface contact -->
                  <!-- PHASE A: contype="0" DISABLED (pushing-only training) -->
                  <!-- PHASE B: Change to contype="2" to enable contact-based strategies -->
                  <geom name="moving_fingertip" type="sphere"
                        class="task_objects"
                        pos="-0.0113 -0.08192077 0.01951059"
                        size="0.008"
                        material="gripper_rubber"
                        friction="1.0 0.003 0.0001"
                        contype="2"
                        conaffinity="2"/>
                </body>
              </body>
            </body>
          </body>
        </body>
      </body>
    </body>

    <!-- Paper (A5 size: 148mm x 210mm, solver-friendly thickness) -->
    <!-- Translated to maintain relative position with robot base at floor center -->
    <!-- Thickness: 0.5mm (0.0005m) - solver-friendly, no visual difference, prevents chatter -->
    <body name="paper" pos="0.025 0.175 0.001">
      <joint name="paper_free" type="free"/>
      <geom name="paper_geom" type="box"
            size="0.105 0.1485 0.0005"
            rgba="0.95 0.95 0.95 1"
            mass="0.005"
            friction="0.60 0.001 0.00005"
            condim="3"
            contype="1"
            conaffinity="2"
            class="task_objects"/>
      <!-- Corner sites for success detection -->
      <site name="paper_corner1" pos="0.074 0.105 0" size="0.002" rgba="0 0 1 0.5"/>
      <site name="paper_corner2" pos="0.074 -0.105 0" size="0.002" rgba="0 0 1 0.5"/>
      <site name="paper_corner3" pos="-0.074 0.105 0" size="0.002" rgba="0 0 1 0.5"/>
      <site name="paper_corner4" pos="-0.074 -0.105 0" size="0.002" rgba="0 0 1 0.5"/>
      <site name="paper_center" pos="0 0 0" size="0.005" rgba="1 1 0 0.5"/>
    </body>

    <!-- Transparent square with red frames: A5 INSIDE (210mm x 148mm), 20mm frame on each side -->
    <!-- Outside dimensions: 250mm x 188mm (A5 + 40mm). Rotated 90°: Long edge parallel to X-axis -->
    <!-- Translated to maintain relative position with robot base at floor center, on floor surface -->
    <body name="tape_square" pos="0.275 0.175 0.001">
      <!-- Invisible tape marker - VISUAL ONLY (no physics) for Phase A -->
      <!-- Tape friction disabled to keep pushing-only strategy space simple -->
      <!-- Can be enabled later by changing contype to "1" if needed -->
      <geom name="tape_contact" type="box"
            size="0.105 0.074 0.00005"
            pos="0 0 -0.00005"
            rgba="0 0 0 0"
            friction="0.9 0.005 0.0005"
            condim="3"
            contype="0"
            conaffinity="0"
            class="task_objects"/>

      <!-- Top frame (long edge, parallel to X-axis) -->
      <geom name="frame_top" type="box"
            size="0.125 0.01 0.0001"
            pos="0 0.084 0"
            rgba="0.8 0.1 0.1 1"
            contype="0"
            conaffinity="0"/>
      <!-- Bottom frame (long edge, parallel to X-axis) -->
      <geom name="frame_bottom" type="box"
            size="0.125 0.01 0.0001"
            pos="0 -0.084 0"
            rgba="0.8 0.1 0.1 1"
            contype="0"
            conaffinity="0"/>
      <!-- Right frame (short edge, parallel to Y-axis) -->
      <geom name="frame_right" type="box"
            size="0.01 0.094 0.0001"
            pos="0.115 0 0"
            rgba="0.8 0.1 0.1 1"
            contype="0"
            conaffinity="0"/>
      <!-- Left frame (short edge, parallel to Y-axis) -->
      <geom name="frame_left" type="box"
            size="0.01 0.094 0.0001"
            pos="-0.115 0 0"
            rgba="0.8 0.1 0.1 1"
            contype="0"
            conaffinity="0"/>
      <site name="tape_center" pos="0 0 0.001" size="0.01" rgba="1 0 0 0.5"/>
    </body>

    <!-- Workspace markers -->
    <body name="markers" pos="0 0 0">
      <site name="workspace_origin" pos="0 0 0" size="0.02" rgba="1 0 0 0.3"/>
    </body>

    <!-- Camera 1: Top-view camera for GR00T vision input -->
    <!-- Positioned 400mm above transparent square center, looking straight down vertically -->
    <!-- 140° FOV for wide-angle workspace view -->
    <!-- xyaxes explicitly defines camera orientation: X right, Y forward, Z up (camera looks down) -->
    <camera name="top_view"
            pos="0.275 0.175 0.4"
            xyaxes="1 0 0  0 1 0"
            fovy="140"/>

    <!-- Laboratory lighting setup (3-point lighting) -->
    <!-- Main overhead light (centered above workspace) -->
    <light name="overhead_main"
           pos="0.3 -0.1 1.2"
           dir="0 0 -1"
           directional="false"
           castshadow="true"
           diffuse="0.8 0.8 0.75"
           specular="0.3 0.3 0.3"
           active="true"/>

    <!-- Front fill light (reduces shadows on paper) -->
    <light name="front_fill"
           pos="0.4 0.3 0.8"
           dir="-0.2 -0.5 -1"
           directional="false"
           castshadow="false"
           diffuse="0.5 0.5 0.48"
           specular="0.1 0.1 0.1"
           active="true"/>

    <!-- Back rim light (adds depth) -->
    <light name="back_rim"
           pos="0.2 -0.6 1.0"
           dir="0.1 0.8 -1"
           directional="false"
           castshadow="false"
           diffuse="0.4 0.4 0.38"
           specular="0.2 0.2 0.2"
           active="true"/>
  </worldbody>

  <actuator>
    <position class="sts3215" name="shoulder_pan" joint="shoulder_pan" forcerange="-3.35 3.35" ctrlrange="-1.91986 1.91986"/>
    <position class="sts3215" name="shoulder_lift" joint="shoulder_lift" forcerange="-3.35 3.35" ctrlrange="-1.74533 1.74533"/>
    <position class="sts3215" name="elbow_flex" joint="elbow_flex" forcerange="-3.35 3.35" ctrlrange="-1.69 1.69"/>
    <position class="sts3215" name="wrist_flex" joint="wrist_flex" forcerange="-3.35 3.35" ctrlrange="-1.65806 1.65806"/>
    <position class="sts3215" name="wrist_roll" joint="wrist_roll" forcerange="-3.35 3.35" ctrlrange="-2.74385 2.84121"/>
    <position class="sts3215" name="gripper" joint="gripper" forcerange="-3.35 3.35" ctrlrange="-0.17453 1.74533"/>
  </actuator>

  <sensor>
    <!-- Joint position sensors -->
    <jointpos name="shoulder_pan_pos" joint="shoulder_pan"/>
    <jointpos name="shoulder_lift_pos" joint="shoulder_lift"/>
    <jointpos name="elbow_flex_pos" joint="elbow_flex"/>
    <jointpos name="wrist_flex_pos" joint="wrist_flex"/>
    <jointpos name="wrist_roll_pos" joint="wrist_roll"/>
    <jointpos name="gripper_pos" joint="gripper"/>

    <!-- Joint velocity sensors -->
    <jointvel name="shoulder_pan_vel" joint="shoulder_pan"/>
    <jointvel name="shoulder_lift_vel" joint="shoulder_lift"/>
    <jointvel name="elbow_flex_vel" joint="elbow_flex"/>
    <jointvel name="wrist_flex_vel" joint="wrist_flex"/>
    <jointvel name="wrist_roll_vel" joint="wrist_roll"/>
    <jointvel name="gripper_vel" joint="gripper"/>

    <!-- End-effector position -->
    <framepos name="ee_pos" objtype="site" objname="ee_site"/>

    <!-- Paper pose -->
    <framepos name="paper_pos" objtype="body" objname="paper"/>
    <framequat name="paper_quat" objtype="body" objname="paper"/>
  </sensor>
</mujoco>
